Workbook

Sheet Inputs -->

Sheet Menu and cost - Russia
H1: Costs of products | P1: Costs of labour
H2: 4 | I2: 6 | J2: 4 | K2: 2 | L2: 3 | P2: 3
B3: ID | C3: Category | D3: Product | E3: Price | F3: Cost | G3: Weight | H3: Dairy Products | I3: Meat / Seafood | J3: Fruits / Veggie | K3: Beverages | L3: Pantry | M3: Total | N3: Portions/hour | O3: Time - min | P3: Time - hrs | Q3: Profit | R3: Производительность
B4: 1 | C4: Appetizer | D4: Salad A | E4: 3 | F4: =SUMPRODUCT(H4:L4,H$2:L$2)*G4 -> 0.78 | G4: 0.2 | H4: 0 | I4: 0 | J4: 0.9 | K4: 0 | L4: 0.1 | M4: =SUM(H4:L4) -> 1 | N4: 20 | O4: =60/N4 -> 3 | P4: =O4/60 -> 0.05 | Q4: =E4-F4-P4*P$2 -> 2.07
B5: =B4+1 -> 2 | C5: Appetizer | D5: Salad B | E5: 3 | F5: =SUMPRODUCT(H5:L5,H$2:L$2)*G5 -> 0.86 | G5: 0.2 | H5: 0 | I5: 0.2 | J5: 0.7 | K5: 0 | L5: 0.1 | M5: =SUM(H5:L5) -> 1 | N5: 20 | O5: =60/N5 -> 3 | P5: =O5/60 -> 0.05 | Q5: =E5-F5-P5*P$2 -> 1.99
B6: =B5+1 -> 3 | C6: Appetizer | D6: Salad C | E6: 3 | F6: =SUMPRODUCT(H6:L6,H$2:L$2)*G6 -> 0.98 | G6: 0.2 | H6: 0 | I6: 0.5 | J6: 0.4 | K6: 0 | L6: 0.1 | M6: =SUM(H6:L6) -> 1 | N6: 20 | O6: =60/N6 -> 3 | P6: =O6/60 -> 0.05 | Q6: =E6-F6-P6*P$2 -> 1.87
B7: =B6+1 -> 4 | C7: Appetizer | D7: Soup A | E7: 2 | F7: =SUMPRODUCT(H7:L7,H$2:L$2)*G7 -> 0.68 | G7: 0.2 | H7: 0.1 | I7: 0 | J7: 0.4 | K7: 0.1 | L7: 0.4 | M7: =SUM(H7:L7) -> 1 | N7: 60 | O7: =60/N7 -> 1 | P7: =O7/60 -> 0.016666667 | Q7: =E7-F7-P7*P$2 -> 1.27
B8: =B7+1 -> 5 | C8: Appetizer | D8: Soup B | E8: 2 | F8: =SUMPRODUCT(H8:L8,H$2:L$2)*G8 -> 0.78 | G8: 0.2 | H8: 0.1 | I8: 0.2 | J8: 0.3 | K8: 0.1 | L8: 0.3 | M8: =SUM(H8:L8) -> 1 | N8: 60 | O8: =60/N8 -> 1 | P8: =O8/60 -> 0.016666667 | Q8: =E8-F8-P8*P$2 -> 1.17
B9: =B8+1 -> 6 | C9: Appetizer | D9: Pirozhok A | E9: 1 | F9: =SUMPRODUCT(H9:L9,H$2:L$2)*G9 -> 0.38 | G9: 0.1 | H9: 0.1 | I9: 0 | J9: 0.75 | K9: 0.05 | L9: 0.1 | M9: =SUM(H9:L9) -> 1 | N9: 30 | O9: =60/N9 -> 2 | P9: =O9/60 -> 0.033333333 | Q9: =E9-F9-P9*P$2 -> 0.52
B10: =B9+1 -> 7 | C10: Appetizer | D10: Pirozhok B | E10: 1 | F10: =SUMPRODUCT(H10:L10,H$2:L$2)*G10 -> 0.48 | G10: 0.1 | H10: 0.1 | I10: 0.5 | J10: 0.25 | K10: 0.05 | L10: 0.1 | M10: =SUM(H10:L10) -> 1 | N10: 30 | O10: =60/N10 -> 2 | P10: =O10/60 -> 0.033333333 | Q10: =E10-F10-P10*P$2 -> 0.42
B11: =B10+1 -> 8 | C11: Entry | D11: Blin A | E11: 3 | F11: =SUMPRODUCT(H11:L11,H$2:L$2)*G11 -> 0.76 | G11: 0.2 | H11: 0.1 | I11: 0 | J11: 0.75 | K11: 0.05 | L11: 0.1 | M11: =SUM(H11:L11) -> 1 | N11: 15 | O11: =60/N11 -> 4 | P11: =O11/60 -> 0.066666667 | Q11: =E11-F11-P11*P$2 -> 2.04
B12: =B11+1 -> 9 | C12: Entry | D12: Blin B | E12: 3 | F12: =SUMPRODUCT(H12:L12,H$2:L$2)*G12 -> 1.14 | G12: 0.3 | H12: 0.3 | I12: 0 | J12: 0.55 | K12: 0.05 | L12: 0.1 | M12: =SUM(H12:L12) -> 1 | N12: 15 | O12: =60/N12 -> 4 | P12: =O12/60 -> 0.066666667 | Q12: =E12-F12-P12*P$2 -> 1.66
B13: =B12+1 -> 10 | C13: Entry | D13: Blin C | E13: 3 | F13: =SUMPRODUCT(H13:L13,H$2:L$2)*G13 -> 1.29 | G13: 0.3 | H13: 0.1 | I13: 0.25 | J13: 0.5 | K13: 0.05 | L13: 0.1 | M13: =SUM(H13:L13) -> 1 | N13: 15 | O13: =60/N13 -> 4 | P13: =O13/60 -> 0.066666667 | Q13: =E13-F13-P13*P$2 -> 1.51
B14: =B13+1 -> 11 | C14: Entry | D14: Blin D | E14: 3 | F14: =SUMPRODUCT(H14:L14,H$2:L$2)*G14 -> 0.92 | G14: 0.2 | H14: 0.2 | I14: 0.4 | J14: 0.25 | K14: 0.05 | L14: 0.1 | M14: =SUM(H14:L14) -> 1 | N14: 10 | O14: =60/N14 -> 6 | P14: =O14/60 -> 0.1 | Q14: =E14-F14-P14*P$2 -> 1.78
B15: =B14+1 -> 12 | C15: Entry | D15: Blin E | E15: 4 | F15: =SUMPRODUCT(H15:L15,H$2:L$2)*G15 -> 1.5 | G15: 0.3 | H15: 0.2 | I15: 0.6 | J15: 0.05 | K15: 0.05 | L15: 0.1 | M15: =SUM(H15:L15) -> 1 | N15: 10 | O15: =60/N15 -> 6 | P15: =O15/60 -> 0.1 | Q15: =E15-F15-P15*P$2 -> 2.2
B16: =B15+1 -> 13 | C16: Entry | D16: Blin F | E16: 4 | F16: =SUMPRODUCT(H16:L16,H$2:L$2)*G16 -> 1.44 | G16: 0.3 | H16: 0.2 | I16: 0.5 | J16: 0.15 | K16: 0.05 | L16: 0.1 | M16: =SUM(H16:L16) -> 1 | N16: 10 | O16: =60/N16 -> 6 | P16: =O16/60 -> 0.1 | Q16: =E16-F16-P16*P$2 -> 2.26
... B29: =B28+1 -> 26 | C29: Beverages | D29: Hot Drink B | E29: 1.5 | F29: =SUMPRODUCT(H29:L29,H$2:L$2)*G29 -> 0.44 | G29: 0.2 | H29: 0 | I29: 0 | J29: 0.1 | K29: 0.9 | L29: 0 | M29: =SUM(H29:L29) -> 1 | N29: 40 | O29: =60/N29 -> 1.5 | P29: =O29/60 -> 0.025 | Q29: =E29-F29-P29*P$2 -> 0.985

Sheet COGS
C2: Dairy Products | D2: Meat / Seafood | E2: Fruits / Veggie | F2: Beverages | G2: Pantry | I2: Labor
B3: Columbus | C3: 8.35 | D3: 14.13 | E3: 12.83 | F3: 5.93 | G3: 5.89 | I3: 10
B4: Cincinnati | C4: 6.79 | D4: 13.56 | E4: 11.34 | F4: 4.56 | G4: 5.34 | I4: 10.5
B5: Cleveland | C5: 6.23 | D5: 13.8 | E5: 12.45 | F5: 5.2 | G5: 5.7 | I5: 11
B6: Las Vegas | C6: 14.56 | D6: 21.88 | E6: 15.54 | F6: 9.83 | G6: 10.78 | I6: 9
B7: Miami | C7: 14.2 | D7: 19.51 | E7: 15.24 | F7: 9.5 | G7: 9.01 | I7: 9.5
B8: Indianapolis | C8: 5.36 | D8: 12.93 | E8: 10.3 | F8: 4.64 | G8: 4.8 | I8: 8
B9: Birmingham | C9: 9.62 | D9: 14.79 | E9: 14.44 | F9: 8.7 | G9: 8.04 | I9: 10
B10: Portland | C10: 9.29 | D10: 14.35 | E10: 13.55 | F10: 8.24 | G10: 6.44 | I10: 14

Sheet Order Composition
C2: Appetizer | D2: Entry | E2: Dessert | F2: Beverages
B3: Columbus | C3: 0.3 | D3: 0.55 | E3: 0.35 | F3: 0.8
B4: Cincinnati | C4: 0.55 | D4: 0.6 | E4: 0.4 | F4: 0.8
B5: Cleveland | C5: 0.4 | D5: 0.85 | E5: 0.55 | F5: 0.75
B6: Las Vegas | C6: 0.55 | D6: 0.9 | E6: 0.7 | F6: 0.9
B7: Miami | C7: 0.5 | D7: 0.85 | E7: 0.8 | F7: 0.95
B8: Indianapolis | C8: 0.4 | D8: 0.6 | E8: 0.65 | F8: 0.8
B9: Birmingham | C9: 0.2 | D9: 0.65 | E9: 0.45 | F9: 0.75
B10: Portland | C10: 0.35 | D10: 0.8 | E10: 0.5 | F10: 0.95
B12: RF | C12: 0.25 | D12: 0.85 | E12: 0.55 | F12: 0.3

Sheet Solution -->
B3: Solution

Sheet Mean order price
M1: Average category price | Q1: Adding average order price
C2: Dairy Products | D2: Meat / Seafood | E2: Fruits / Veggie | F2: Beverages | G2: Pantry | H2: Labor | I2: Appetizer | J2: Entry | K2: Dessert | L2: Beverages | M2: Appetizer | N2: Entry | O2: Dessert | P2: Beverages | Q2: Appetizer | R2: Entry | S2: Dessert | T2: Beverages | V2: Mean order, $
B3: Columbus | C3: =VLOOKUP(B3,COGS!$B$2:$I$10,2,FALSE) -> 8.35 | D3: =VLOOKUP($B3,COGS!$B$2:$I$10,3,FALSE) -> 14.13 | E3: =VLOOKUP($B3,COGS!$B$2:$I$10,4,FALSE) -> 12.83 | F3: =VLOOKUP($B3,COGS!$B$2:$I$10,5,FALSE) -> 5.93 | G3: =VLOOKUP($B3,COGS!$B$2:$I$10,6,FALSE) -> 5.89 | H3: =VLOOKUP($B3,COGS!$B$2:$I$10,8,FALSE) -> 10 | I3: 0.3 | J3: 0.55 | K3: 0.35 | L3: 0.8 | M3: =AVERAGEIFS('Menu and cost - USA by city'!$E:$E,'Menu and cost - USA by city'!$A:$A,'Mean order price'!$B3,'Menu and cost - USA by city'!$C:$C,'Mean order price'!I$2) -> 2.8571429 | N3: =AVERAGEIFS('Menu and cost - USA by city'!$E:$E,'Menu and cost - USA by city'!$A:$A,'Mean order price'!$B3,'Menu and cost - USA by city'!$C:$C,'Mean order price'!J$2) -> 4.8 | O3: =AVERAGEIFS('Menu and cost - USA by city'!$E:$E,'Menu and cost - USA by city'!$A:$A,'Mean order price'!$B3,'Menu and cost - USA by city'!$C:$C,'Mean order price'!K$2) -> 3.3333333 | P3: =AVERAGEIFS('Menu and cost - USA by city'!$E:$E,'Menu and cost - USA by city'!$A:$A,'Mean order price'!$B3,'Menu and cost - USA by city'!$C:$C,'Mean order price'!L$2) -> 2.2222222 | Q3: =I3*M3 -> 0.85714286 | R3: =J3*N3 -> 2.64 | S3: =K3*O3 -> 1.1666667 | T3: =L3*P3 -> 1.7777778 | V3: =SUMPRODUCT(I3:L3,M3:P3) -> 6.4415873
B4: Cincinnati | C4: =VLOOKUP(B4,COGS!$B$2:$I$10,2,FALSE) -> 6.79 | D4: =VLOOKUP($B4,COGS!$B$2:$I$10,3,FALSE) -> 13.56 | E4: =VLOOKUP($B4,COGS!$B$2:$I$10,4,FALSE) -> 11.34 | F4: =VLOOKUP($B4,COGS!$B$2:$I$10,5,FALSE) -> 4.56 | G4: =VLOOKUP($B4,COGS!$B$2:$I$10,6,FALSE) -> 5.34 | H4: =VLOOKUP($B4,COGS!$B$2:$I$10,8,FALSE) -> 10.5 | I4: 0.55 | J4: 0.6 | K4: 0.4 | L4: 0.8 | M4: =AVERAGEIFS('Menu and cost - USA by city'!$E:$E,'Menu and cost - USA by city'!$A:$A,'Mean order price'!$B4,'Menu and cost - USA by city'!$C:$C,'Mean order price'!I$2) -> 3 | N4: =AVERAGEIFS('Menu and cost - USA by city'!$E:$E,'Menu and cost - USA by city'!$A:$A,'Mean order price'!$B4,'Menu and cost - USA by city'!$C:$C,'Mean order price'!J$2) -> 5.04 | O4: =AVERAGEIFS('Menu and cost - USA by city'!$E:$E,'Menu and cost - USA by city'!$A:$A,'Mean order price'!$B4,'Menu and cost - USA by city'!$C:$C,'Mean order price'!K$2) -> 3.5 | P4: =AVERAGEIFS('Menu and cost - USA by city'!$E:$E,'Menu and cost - USA by city'!$A:$A,'Mean order price'!$B4,'Menu and cost - USA by city'!$C:$C,'Mean order price'!L$2) -> 2.3333333 | Q4: =I4*M4 -> 1.65 | R4: =J4*N4 -> 3.024 | S4: =K4*O4 -> 1.4 | T4: =L4*P4 -> 1.8666667 | V4: =SUMPRODUCT(I4:L4,M4:P4) -> 7.9406667
B5: Cleveland | C5: =VLOOKUP(B5,COGS!$B$2:$I$10,2,FALSE) -> 6.23 | D5: =VLOOKUP($B5,COGS!$B$2:$I$10,3,FALSE) -> 13.8 | E5: =VLOOKUP($B5,COGS!$B$2:$I$10,4,FALSE) -> 12.45 | F5: =VLOOKUP($B5,COGS!$B$2:$I$10,5,FALSE) -> 5.2 | G5: =VLOOKUP($B5,COGS!$B$2:$I$10,6,FALSE) -> 5.7 | H5: =VLOOKUP($B5,COGS!$B$2:$I$10,8,FALSE) -> 11 | I5: 0.4 | J5: 0.85 | K5: 0.55 | L5: 0.75 | M5: =AVERAGEIFS('Menu and cost - USA by city'!$E:$E,'Menu and cost - USA by city'!$A:$A,'Mean order price'!$B5,'Menu and cost - USA by city'!$C:$C,'Mean order price'!I$2) -> 3.1428571 | N5: =AVERAGEIFS('Menu and cost - USA by city'!$E:$E,'Menu and cost - USA by city'!$A:$A,'Mean order price'!$B5,'Menu and cost - USA by city'!$C:$C,'Mean order price'!J$2) -> 5.28 | O5: =AVERAGEIFS('Menu and cost - USA by city'!$E:$E,'Menu and cost - USA by city'!$A:$A,'Mean order price'!$B5,'Menu and cost - USA by city'!$C:$C,'Mean order price'!K$2) -> 3.6666667 | P5: =AVERAGEIFS('Menu and cost - USA by city'!$E:$E,'Menu and cost - USA by city'!$A:$A,'Mean order price'!$B5,'Menu and cost - USA by city'!$C:$C,'Mean order price'!L$2) -> 2.4444444 | Q5: =I5*M5 -> 1.2571429 | R5: =J5*N5 -> 4.488 | S5: =K5*O5 -> 2.0166667 | T5: =L5*P5 -> 1.8333333 | V5: =SUMPRODUCT(I5:L5,M5:P5) -> 9.5951429
B6: Las Vegas | C6: =VLOOKUP(B6,COGS!$B$2:$I$10,2,FALSE) -> 14.56 | D6: =VLOOKUP($B6,COGS!$B$2:$I$10,3,FALSE) -> 21.88 | E6: =VLOOKUP($B6,COGS!$B$2:$I$10,4,FALSE) -> 15.54 | F6: =VLOOKUP($B6,COGS!$B$2:$I$10,5,FALSE) -> 9.83 | G6: =VLOOKUP($B6,COGS!$B$2:$I$10,6,FALSE) -> 10.78 | H6: =VLOOKUP($B6,COGS!$B$2:$I$10,8,FALSE) -> 9 | I6: 0.55 | J6: 0.9 | K6: 0.7 | L6: 0.9 | M6: =AVERAGEIFS('Menu and cost - USA by city'!$E:$E,'Menu and cost - USA by city'!$A:$A,'Mean order price'!$B6,'Menu and cost - USA by city'!$C:$C,'Mean order price'!I$2) -> 2.5714286 | N6: =AVERAGEIFS('Menu and cost - USA by city'!$E:$E,'Menu and cost - USA by city'!$A:$A,'Mean order price'!$B6,'Menu and cost - USA by city'!$C:$C,'Mean order price'!J$2) -> 4.32 | O6: =AVERAGEIFS('Menu and cost - USA by city'!$E:$E,'Menu and cost - USA by city'!$A:$A,'Mean order price'!$B6,'Menu and cost - USA by city'!$C:$C,'Mean order price'!K$2) -> 3 | P6: =AVERAGEIFS('Menu and cost - USA by city'!$E:$E,'Menu and cost - USA by city'!$A:$A,'Mean order price'!$B6,'Menu and cost - USA by city'!$C:$C,'Mean order price'!L$2) -> 2 | Q6: =I6*M6 -> 1.4142857 | R6: =J6*N6 -> 3.888 | S6: =K6*O6 -> 2.1 | T6: =L6*P6 -> 1.8 | V6: =SUMPRODUCT(I6:L6,M6:P6) -> 9.2022857
B7: Miami | C7: =VLOOKUP(B7,COGS!$B$2:$I$10,2,FALSE) -> 14.2 | D7: =VLOOKUP($B7,COGS!$B$2:$I$10,3,FALSE) -> 19.51 | E7: =VLOOKUP($B7,COGS!$B$2:$I$10,4,FALSE) -> 15.24 | F7: =VLOOKUP($B7,COGS!$B$2:$I$10,5,FALSE) -> 9.5 | G7: =VLOOKUP($B7,COGS!$B$2:$I$10,6,FALSE) -> 9.01 | H7: =VLOOKUP($B7,COGS!$B$2:$I$10,8,FALSE) -> 9.5 | I7: 0.5 | J7: 0.85 | K7: 0.8 | L7: 0.95 | M7: =AVERAGEIFS('Menu and cost - USA by city'!$E:$E,'Menu and cost - USA by city'!$A:$A,'Mean order price'!$B7,'Menu and cost - USA by city'!$C:$C,'Mean order price'!I$2) -> 2.7142857 | N7: =AVERAGEIFS('Menu and cost - USA by city'!$E:$E,'Menu and cost - USA by city'!$A:$A,'Mean order price'!$B7,'Menu and cost - USA by city'!$C:$C,'Mean order price'!J$2) -> 4.56 | O7: =AVERAGEIFS('Menu and cost - USA by city'!$E:$E,'Menu and cost - USA by city'!$A:$A,'Mean order price'!$B7,'Menu and cost - USA by city'!$C:$C,'Mean order price'!K$2) -> 3.1666667 | P7: =AVERAGEIFS('Menu and cost - USA by city'!$E:$E,'Menu and cost - USA by city'!$A:$A,'Mean order price'!$B7,'Menu and cost - USA by city'!$C:$C,'Mean order price'!L$2) -> 2.1111111 | Q7: =I7*M7 -> 1.3571429 | R7: =J7*N7 -> 3.876 | S7: =K7*O7 -> 2.5333333 | T7: =L7*P7 -> 2.0055556 | V7: =SUMPRODUCT(I7:L7,M7:P7) -> 9.7720317
B8: Indianapolis | C8: =VLOOKUP(B8,COGS!$B$2:$I$10,2,FALSE) -> 5.36 | D8: =VLOOKUP($B8,COGS!$B$2:$I$10,3,FALSE) -> 12.93 | E8: =VLOOKUP($B8,COGS!$B$2:$I$10,4,FALSE) -> 10.3 | F8: =VLOOKUP($B8,COGS!$B$2:$I$10,5,FALSE) -> 4.64 | G8: =VLOOKUP($B8,COGS!$B$2:$I$10,6,FALSE) -> 4.8 | H8: =VLOOKUP($B8,COGS!$B$2:$I$10,8,FALSE) -> 8 | I8: 0.4 | J8: 0.6 | K8: 0.65 | L8: 0.8 | M8: =AVERAGEIFS('Menu and cost - USA by city'!$E:$E,'Menu and cost - USA by city'!$A:$A,'Mean order price'!$B8,'Menu and cost - USA by city'!$C:$C,'Mean order price'!I$2) -> 2.2857143 | N8: =AVERAGEIFS('Menu and cost - USA by city'!$E:$E,'Menu and cost - USA by city'!$A:$A,'Mean order price'!$B8,'Menu and cost - USA by city'!$C:$C,'Mean order price'!J$2) -> 3.84 | O8: =AVERAGEIFS('Menu and cost - USA by city'!$E:$E,'Menu and cost - USA by city'!$A:$A,'Mean order price'!$B8,'Menu and cost - USA by city'!$C:$C,'Mean order price'!K$2) -> 2.6666667 | P8: =AVERAGEIFS('Menu and cost - USA by city'!$E:$E,'Menu and cost - USA by city'!$A:$A,'Mean order price'!$B8,'Menu and cost - USA by city'!$C:$C,'Mean order price'!L$2) -> 1.7777778 | Q8: =I8*M8 -> 0.91428571 | R8: =J8*N8 -> 2.304 | S8: =K8*O8 -> 1.7333333 | T8: =L8*P8 -> 1.4222222 | V8: =SUMPRODUCT(I8:L8,M8:P8) -> 6.3738413
B9: Birmingham | C9: =VLOOKUP(B9,COGS!$B$2:$I$10,2,FALSE) -> 9.62 | D9: =VLOOKUP($B9,COGS!$B$2:$I$10,3,FALSE) -> 14.79 | E9: =VLOOKUP($B9,COGS!$B$2:$I$10,4,FALSE) -> 14.44 | F9: =VLOOKUP($B9,COGS!$B$2:$I$10,5,FALSE) -> 8.7 | G9: =VLOOKUP($B9,COGS!$B$2:$I$10,6,FALSE) -> 8.04 | H9: =VLOOKUP($B9,COGS!$B$2:$I$10,8,FALSE) -> 10 | I9: 0.2 | J9: 0.65 | K9: 0.45 | L9: 0.75 | M9: =AVERAGEIFS('Menu and cost - USA by city'!$E:$E,'Menu and cost - USA by city'!$A:$A,'Mean order price'!$B9,'Menu and cost - USA by city'!$C:$C,'Mean order price'!I$2) -> 2.8571429 | N9: =AVERAGEIFS('Menu and cost - USA by city'!$E:$E,'Menu and cost - USA by city'!$A:$A,'Mean order price'!$B9,'Menu and cost - USA by city'!$C:$C,'Mean order price'!J$2) -> 4.8 | O9: =AVERAGEIFS('Menu and cost - USA by city'!$E:$E,'Menu and cost - USA by city'!$A:$A,'Mean order price'!$B9,'Menu and cost - USA by city'!$C:$C,'Mean order price'!K$2) -> 3.3333333 | P9: =AVERAGEIFS('Menu and cost - USA by city'!$E:$E,'Menu and cost - USA by city'!$A:$A,'Mean order price'!$B9,'Menu and cost - USA by city'!$C:$C,'Mean order price'!L$2) -> 2.2222222 | Q9: =I9*M9 -> 0.57142857 | R9: =J9*N9 -> 3.12 | S9: =K9*O9 -> 1.5 | T9: =L9*P9 -> 1.6666667 | V9: =SUMPRODUCT(I9:L9,M9:P9) -> 6.8580952
B10: Portland | C10: =VLOOKUP(B10,COGS!$B$2:$I$10,2,FALSE) -> 9.29 | D10: =VLOOKUP($B10,COGS!$B$2:$I$10,3,FALSE) -> 14.35 | E10: =VLOOKUP($B10,COGS!$B$2:$I$10,4,FALSE) -> 13.55 | F10: =VLOOKUP($B10,COGS!$B$2:$I$10,5,FALSE) -> 8.24 | G10: =VLOOKUP($B10,COGS!$B$2:$I$10,6,FALSE) -> 6.44 | H10: =VLOOKUP($B10,COGS!$B$2:$I$10,8,FALSE) -> 14 | I10: 0.35 | J10: 0.8 | K10: 0.5 | L10: 0.95 | M10: =AVERAGEIFS('Menu and cost - USA by city'!$E:$E,'Menu and cost - USA by city'!$A:$A,'Mean order price'!$B10,'Menu and cost - USA by city'!$C:$C,'Mean order price'!I$2) -> 4 | N10: =AVERAGEIFS('Menu and cost - USA by city'!$E:$E,'Menu and cost - USA by city'!$A:$A,'Mean order price'!$B10,'Menu and cost - USA by city'!$C:$C,'Mean order price'!J$2) -> 6.72 | O10: =AVERAGEIFS('Menu and cost - USA by city'!$E:$E,'Menu and cost - USA by city'!$A:$A,'Mean order price'!$B10,'Menu and cost - USA by city'!$C:$C,'Mean order price'!K$2) -> 4.6666667 | P10: =AVERAGEIFS('Menu and cost - USA by city'!$E:$E,'Menu and cost - USA by city'!$A:$A,'Mean order price'!$B10,'Menu and cost - USA by city'!$C:$C,'Mean order price'!L$2) -> 3.1111111 | Q10: =I10*M10 -> 1.4 | R10: =J10*N10 -> 5.376 | S10: =K10*O10 -> 2.3333333 | T10: =L10*P10 -> 2.9555556 | V10: =SUMPRODUCT(I10:L10,M10:P10) -> 12.064889
B12: RF | I12: 0.25 | J12: 0.85 | K12: 0.55 | L12: 0.3

Sheet Menu and cost - USA by city
A3: City | B3: ID | C3: Category | D3: Product | E3: Price | F3: Cost(with labour) | G3: Weight | H3: Dairy Products | I3: Meat / Seafood | J3: Fruits / Veggie | K3: Beverages | L3: Pantry | M3: Total | N3: Portions/hour | O3: Time - min | P3: Time - hrs | Q3: Profit | R3: Gross profit | S3: Order | T3: Order * Profit | U3: Gross Profit per Average Order | V3: Costs (with labor) per Average Order | W3: Labour cost, $ | X3: Labor costs per avg order
A4: Columbus | B4: 1 | C4: Appetizer | D4: Salad A | E4: ='Menu and cost - Russia'!E4*(COGS!I3/'Menu and cost - Russia'!$P$2)*0.4 -> 4 | F4: =SUMPRODUCT(H4:L4,'Mean order price'!$C$3:$G$3)*G4+P4*'Mean order price'!$H$3 -> 2.9272 | G4: 0.2 | H4: 0 | I4: 0 | J4: 0.9 | K4: 0 | L4: 0.1 | M4: =SUM(H4:L4) -> 1 | N4: 20 | O4: =60/N4 -> 3 | P4: =O4/60 -> 0.05 | Q4: =E4-F4 -> 1.0728 | R4: =Таблица1[[#This Row],[Profit]]/Таблица1[[#This Row],[Price]] -> 0.2682 | S4: =VLOOKUP($A4,'Order Composition'!$B$2:$F$10,MATCH($C4,'Order Composition'!$B$2:$F$2,0),0) -> 0.3 | T4: =S4*Q4 -> 0.32184 | U4: =Таблица1[[#This Row],[Price]]*Таблица1[[#This Row],[Order]] -> 1.2 | V4: =Таблица1[[#This Row],[Cost(with labour)]]*Таблица1[[#This Row],[Order]] -> 0.87816 | W4: =VLOOKUP($A4,'Mean order price'!$B$2:$H$10,7,0) -> 10 | X4: =W4*P4 -> 0.5
A5: Columbus | B5: =B4+1 -> 2 | C5: Appetizer | D5: Salad B | E5: =VLOOKUP('Menu and cost - USA by city'!D5,'Menu and cost - Russia'!$D$4:$P$29,2,FALSE)*(VLOOKUP('Menu and cost - USA by city'!A5,COGS!$B$3:$I$10,8,FALSE)/3)*0.4 -> 4 | F5: =SUMPRODUCT(H5:L5,'Mean order price'!$C$3:$G$3)*G5+P5*'Mean order price'!$H$3 -> 2.9792 | G5: 0.2 | H5: 0 | I5: 0.2 | J5: 0.7 | K5: 0 | L5: 0.1 | M5: =SUM(H5:L5) -> 1 | N5: 20 | O5: =60/N5 -> 3 | P5: =O5/60 -> 0.05 | Q5: =E5-F5 -> 1.0208 | R5: =Таблица1[[#This Row],[Profit]]/Таблица1[[#This Row],[Price]] -> 0.2552 | S5: =VLOOKUP($A5,'Order Composition'!$B$2:$F$10,MATCH($C5,'Order Composition'!$B$2:$F$2,0),0) -> 0.3 | T5: =S5*Q5 -> 0.30624 | U5: =Таблица1[[#This Row],[Price]]*Таблица1[[#This Row],[Order]] -> 1.2 | V5: =Таблица1[[#This Row],[Cost(with labour)]]*Таблица1[[#This Row],[Order]] -> 0.89376 | W5: =VLOOKUP($A5,'Mean order price'!$B$2:$H$10,7,0) -> 10 | X5: =W5*P5 -> 0.5
A6: Columbus | B6: =B5+1 -> 3 | C6: Appetizer | D6: Salad C | E6: =VLOOKUP('Menu and cost - USA by city'!D6,'Menu and cost - Russia'!$D$4:$P$29,2,FALSE)*(VLOOKUP('Menu and cost - USA by city'!A6,COGS!$B$3:$I$10,8,FALSE)/3)*0.4 -> 4 | F6: =SUMPRODUCT(H6:L6,'Mean order price'!$C$3:$G$3)*G6+P6*'Mean order price'!$H$3 -> 3.0572 | G6: 0.2 | H6: 0 | I6: 0.5 | J6: 0.4 | K6: 0 | L6: 0.1 | M6: =SUM(H6:L6) -> 1 | N6: 20 | O6: =60/N6 -> 3 | P6: =O6/60 -> 0.05 | Q6: =E6-F6 -> 0.9428 | R6: =Таблица1[[#This Row],[Profit]]/Таблица1[[#This Row],[Price]] -> 0.2357 | S6: =VLOOKUP($A6,'Order Composition'!$B$2:$F$10,MATCH($C6,'Order Composition'!$B$2:$F$2,0),0) -> 0.3 | T6: =S6*Q6 -> 0.28284 | U6: =Таблица1[[#This Row],[Price]]*Таблица1[[#This Row],[Order]] -> 1.2 | V6: =Таблица1[[#This Row],[Cost(with labour)]]*Таблица1[[#This Row],[Order]] -> 0.91716 | W6: =VLOOKUP($A6,'Mean order price'!$B$2:$H$10,7,0) -> 10 | X6: =W6*P6 -> 0.5
A7: Columbus | B7: =B6+1 -> 4 | C7: Appetizer | D7: Soup A | E7: =VLOOKUP('Menu and cost - USA by city'!D7,'Menu and cost - Russia'!$D$4:$P$29,2,FALSE)*(VLOOKUP('Menu and cost - USA by city'!A7,COGS!$B$3:$I$10,8,FALSE)/3)*0.4 -> 2.6666667 | F7: =SUMPRODUCT(H7:L7,'Mean order price'!$C$3:$G$3)*G7+P7*'Mean order price'!$H$3 -> 1.9498667 | G7: 0.2 | H7: 0.1 | I7: 0 | J7: 0.4 | K7: 0.1 | L7: 0.4 | M7: =SUM(H7:L7) -> 1 | N7: 60 | O7: =60/N7 -> 1 | P7: =O7/60 -> 0.016666667 | Q7: =E7-F7 -> 0.7168 | R7: =Таблица1[[#This Row],[Profit]]/Таблица1[[#This Row],[Price]] -> 0.2688 | S7: =VLOOKUP($A7,'Order Composition'!$B$2:$F$10,MATCH($C7,'Order Composition'!$B$2:$F$2,0),0) -> 0.3 | T7: =S7*Q7 -> 0.21504 | U7: =Таблица1[[#This Row],[Price]]*Таблица1[[#This Row],[Order]] -> 0.8 | V7: =Таблица1[[#This Row],[Cost(with labour)]]*Таблица1[[#This Row],[Order]] -> 0.58496 | W7: =VLOOKUP($A7,'Mean order price'!$B$2:$H$10,7,0) -> 10 | X7: =W7*P7 -> 0.16666667
A8: Columbus | B8: =B7+1 -> 5 | C8: Appetizer | D8: Soup B | E8: =VLOOKUP('Menu and cost - USA by city'!D8,'Menu and cost - Russia'!$D$4:$P$29,2,FALSE)*(VLOOKUP('Menu and cost - USA by city'!A8,COGS!$B$3:$I$10,8,FALSE)/3)*0.4 -> 2.6666667 | F8: =SUMPRODUCT(H8:L8,'Mean order price'!$C$3:$G$3)*G8+P8*'Mean order price'!$H$3 -> 2.1406667 | G8: 0.2 | H8: 0.1 | I8: 0.2 | J8: 0.3 | K8: 0.1 | L8: 0.3 | M8: =SUM(H8:L8) -> 1 | N8: 60 | O8: =60/N8 -> 1 | P8: =O8/60 -> 0.016666667 | Q8: =E8-F8 -> 0.526 | R8: =Таблица1[[#This Row],[Profit]]/Таблица1[[#This Row],[Price]] -> 0.19725 | S8: =VLOOKUP($A8,'Order Composition'!$B$2:$F$10,MATCH($C8,'Order Composition'!$B$2:$F$2,0),0) -> 0.3 | T8: =S8*Q8 -> 0.1578 | U8: =Таблица1[[#This Row],[Price]]*Таблица1[[#This Row],[Order]] -> 0.8 | V8: =Таблица1[[#This Row],[Cost(with labour)]]*Таблица1[[#This Row],[Order]] -> 0.6422 | W8: =VLOOKUP($A8,'Mean order price'!$B$2:$H$10,7,0) -> 10 | X8: =W8*P8 -> 0.16666667
A9: Columbus | B9: =B8+1 -> 6 | C9: Appetizer | D9: Pirozhok A | E9: =VLOOKUP('Menu and cost - USA by city'!D9,'Menu and cost - Russia'!$D$4:$P$29,2,FALSE)*(VLOOKUP('Menu and cost - USA by city'!A9,COGS!$B$3:$I$10,8,FALSE)/3)*0.4 -> 1.3333333 | F9: =SUMPRODUCT(H9:L9,'Mean order price'!$C$3:$G$3)*G9+P9*'Mean order price'!$H$3 -> 1.4676333 | G9: 0.1 | H9: 0.1 | I9: 0 | J9: 0.75 | K9: 0.05 | L9: 0.1 | M9: =SUM(H9:L9) -> 1 | N9: 30 | O9: =60/N9 -> 2 | P9: =O9/60 -> 0.033333333 | Q9: =E9-F9 -> -0.1343 | R9: =Таблица1[[#This Row],[Profit]]/Таблица1[[#This Row],[Price]] -> -0.100725 | S9: =VLOOKUP($A9,'Order Composition'!$B$2:$F$10,MATCH($C9,'Order Composition'!$B$2:$F$2,0),0) -> 0.3 | T9: =S9*Q9 -> -0.04029 | U9: =Таблица1[[#This Row],[Price]]*Таблица1[[#This Row],[Order]] -> 0.4 | V9: =Таблица1[[#This Row],[Cost(with labour)]]*Таблица1[[#This Row],[Order]] -> 0.44029 | W9: =VLOOKUP($A9,'Mean order price'!$B$2:$H$10,7,0) -> 10 | X9: =W9*P9 -> 0.33333333
A10: Columbus | B10: =B9+1 -> 7 | C10: Appetizer | D10: Pirozhok B | E10: =VLOOKUP('Menu and cost - USA by city'!D10,'Menu and cost - Russia'!$D$4:$P$29,2,FALSE)*(VLOOKUP('Menu and cost - USA by city'!A10,COGS!$B$3:$I$10,8,FALSE)/3)*0.4 -> 1.3333333 | F10: =SUMPRODUCT(H10:L10,'Mean order price'!$C$3:$G$3)*G10+P10*'Mean order price'!$H$3 -> 1.5326333 | G10: 0.1 | H10: 0.1 | I10: 0.5 | J10: 0.25 | K10: 0.05 | L10: 0.1 | M10: =SUM(H10:L10) -> 1 | N10: 30 | O10: =60/N10 -> 2 | P10: =O10/60 -> 0.033333333 | Q10: =E10-F10 -> -0.1993 | R10: =Таблица1[[#This Row],[Profit]]/Таблица1[[#This Row],[Price]] -> -0.149475 | S10: =VLOOKUP($A10,'Order Composition'!$B$2:$F$10,MATCH($C10,'Order Composition'!$B$2:$F$2,0),0) -> 0.3 | T10: =S10*Q10 -> -0.05979 | U10: =Таблица1[[#This Row],[Price]]*Таблица1[[#This Row],[Order]] -> 0.4 | V10: =Таблица1[[#This Row],[Cost(with labour)]]*Таблица1[[#This Row],[Order]] -> 0.45979 | W10: =VLOOKUP($A10,'Mean order price'!$B$2:$H$10,7,0) -> 10 | X10: =W10*P10 -> 0.33333333
A11: Columbus | B11: =B10+1 -> 8 | C11: Entry | D11: Blin A | E11: =VLOOKUP('Menu and cost - USA by city'!D11,'Menu and cost - Russia'!$D$4:$P$29,2,FALSE)*(VLOOKUP('Menu and cost - USA by city'!A11,COGS!$B$3:$I$10,8,FALSE)/3)*0.4 -> 4 | F11: =SUMPRODUCT(H11:L11,'Mean order price'!$C$3:$G$3)*G11+P11*'Mean order price'!$H$3 -> 2.9352667 | G11: 0.2 | H11: 0.1 | I11: 0 | J11: 0.75 | K11: 0.05 | L11: 0.1 | M11: =SUM(H11:L11) -> 1 | N11: 15 | O11: =60/N11 -> 4 | P11: =O11/60 -> 0.066666667 | Q11: =E11-F11 -> 1.0647333 | R11: =Таблица1[[#This Row],[Profit]]/Таблица1[[#This Row],[Price]] -> 0.26618333 | S11: =VLOOKUP($A11,'Order Composition'!$B$2:$F$10,MATCH($C11,'Order Composition'!$B$2:$F$2,0),0) -> 0.55 | T11: =S11*Q11 -> 0.58560333 | U11: =Таблица1[[#This Row],[Price]]*Таблица1[[#This Row],[Order]] -> 2.2 | V11: =Таблица1[[#This Row],[Cost(with labour)]]*Таблица1[[#This Row],[Order]] -> 1.6143967 | W11: =VLOOKUP($A11,'Mean order price'!$B$2:$H$10,7,0) -> 10 | X11: =W11*P11 -> 0.66666667
A12: Columbus | B12: =B11+1 -> 9 | C12: Entry | D12: Blin B | E12: =VLOOKUP('Menu and cost - USA by city'!D12,'Menu and cost - Russia'!$D$4:$P$29,2,FALSE)*(VLOOKUP('Menu and cost - USA by city'!A12,COGS!$B$3:$I$10,8,FALSE)/3)*0.4 -> 4 | F12: =SUMPRODUCT(H12:L12,'Mean order price'!$C$3:$G$3)*G12+P12*'Mean order price'!$H$3 -> 3.8007667 | G12: 0.3 | H12: 0.3 | I12: 0 | J12: 0.55 | K12: 0.05 | L12: 0.1 | M12: =SUM(H12:L12) -> 1 | N12: 15 | O12: =60/N12 -> 4 | P12: =O12/60 -> 0.066666667 | Q12: =E12-F12 -> 0.19923333 | R12: =Таблица1[[#This Row],[Profit]]/Таблица1[[#This Row],[Price]] -> 0.049808333 | S12: =VLOOKUP($A12,'Order Composition'!$B$2:$F$10,MATCH($C12,'Order Composition'!$B$2:$F$2,0),0) -> 0.55 | T12: =S12*Q12 -> 0.10957833 | U12: =Таблица1[[#This Row],[Price]]*Таблица1[[#This Row],[Order]] -> 2.2 | V12: =Таблица1[[#This Row],[Cost(with labour)]]*Таблица1[[#This Row],[Order]] -> 2.0904217 | W12: =VLOOKUP($A12,'Mean order price'!$B$2:$H$10,7,0) -> 10 | X12: =W12*P12 -> 0.66666667
A13: Columbus | B13: =B12+1 -> 10 | C13: Entry | D13: Blin C | E13: =VLOOKUP('Menu and cost - USA by city'!D13,'Menu and cost - Russia'!$D$4:$P$29,2,FALSE)*(VLOOKUP('Menu and cost - USA by city'!A13,COGS!$B$3:$I$10,8,FALSE)/3)*0.4 -> 4 | F13: =SUMPRODUCT(H13:L13,'Mean order price'!$C$3:$G$3)*G13+P13*'Mean order price'!$H$3 -> 4.1670667 | G13: 0.3 | H13: 0.1 | I13: 0.25 | J13: 0.5 | K13: 0.05 | L13: 0.1 | M13: =SUM(H13:L13) -> 1 | N13: 15 | O13: =60/N13 -> 4 | P13: =O13/60 -> 0.066666667 | Q13: =E13-F13 -> -0.16706667 | R13: =Таблица1[[#This Row],[Profit]]/Таблица1[[#This Row],[Price]] -> -0.041766667 | S13: =VLOOKUP($A13,'Order Composition'!$B$2:$F$10,MATCH($C13,'Order Composition'!$B$2:$F$2,0),0) -> 0.55 | T13: =S13*Q13 -> -0.091886667 | U13: =Таблица1[[#This Row],[Price]]*Таблица1[[#This Row],[Order]] -> 2.2 | V13: =Таблица1[[#This Row],[Cost(with labour)]]*Таблица1[[#This Row],[Order]] -> 2.2918867 | W13: =VLOOKUP($A13,'Mean order price'!$B$2:$H$10,7,0) -> 10 | X13: =W13*P13 -> 0.66666667
A14: Columbus | B14: =B13+1 -> 11 | C14: Entry | D14: Blin D | E14: =VLOOKUP('Menu and cost - USA by city'!D14,'Menu and cost - Russia'!$D$4:$P$29,2,FALSE)*(VLOOKUP('Menu and cost - USA by city'!A14,COGS!$B$3:$I$10,8,FALSE)/3)*0.4 -> 4 | F14: =SUMPRODUCT(H14:L14,'Mean order price'!$C$3:$G$3)*G14+P14*'Mean order price'!$H$3 -> 3.283 | G14: 0.2 | H14: 0.2 | I14: 0.4 | J14: 0.25 | K14: 0.05 | L14: 0.1 | M14: =SUM(H14:L14) -> 1 | N14: 10 | O14: =60/N14 -> 6 | P14: =O14/60 -> 0.1 | Q14: =E14-F14 -> 0.717 | R14: =Таблица1[[#This Row],[Profit]]/Таблица1[[#This Row],[Price]] -> 0.17925 | S14: =VLOOKUP($A14,'Order Composition'!$B$2:$F$10,MATCH($C14,'Order Composition'!$B$2:$F$2,0),0) -> 0.55 | T14: =S14*Q14 -> 0.39435 | U14: =Таблица1[[#This Row],[Price]]*Таблица1[[#This Row],[Order]] -> 2.2 | V14: =Таблица1[[#This Row],[Cost(with labour)]]*Таблица1[[#This Row],[Order]] -> 1.80565 | W14: =VLOOKUP($A14,'Mean order price'!$B$2:$H$10,7,0) -> 10 | X14: =W14*P14 -> 1
A15: Columbus | B15: =B14+1 -> 12 | C15: Entry | D15: Blin E | E15: =VLOOKUP('Menu and cost - USA by city'!D15,'Menu and cost - Russia'!$D$4:$P$29,2,FALSE)*(VLOOKUP('Menu and cost - USA by city'!A15,COGS!$B$3:$I$10,8,FALSE)/3)*0.4 -> 5.3333333 | F15: =SUMPRODUCT(H15:L15,'Mean order price'!$C$3:$G$3)*G15+P15*'Mean order price'!$H$3 -> 4.5025 | G15: 0.3 | H15: 0.2 | I15: 0.6 | J15: 0.05 | K15: 0.05 | L15: 0.1 | M15: =SUM(H15:L15) -> 1 | N15: 10 | O15: =60/N15 -> 6 | P15: =O15/60 -> 0.1 | Q15: =E15-F15 -> 0.83083333 | R15: =Таблица1[[#This Row],[Profit]]/Таблица1[[#This Row],[Price]] -> 0.15578125 | S15: =VLOOKUP($A15,'Order Composition'!$B$2:$F$10,MATCH($C15,'Order Composition'!$B$2:$F$2,0),0) -> 0.55 | T15: =S15*Q15 -> 0.45695833 | U15: =Таблица1[[#This Row],[Price]]*Таблица1[[#This Row],[Order]] -> 2.9333333 | V15: =Таблица1[[#This Row],[Cost(with labour)]]*Таблица1[[#This Row],[Order]] -> 2.476375 | W15: =VLOOKUP($A15,'Mean order price'!$B$2:$H$10,7,0) -> 10 | X15: =W15*P15 -> 1
A16: Columbus | B16: =B15+1 -> 13 | C16: Entry | D16: Blin F | E16: =VLOOKUP('Menu and cost - USA by city'!D16,'Menu and cost - Russia'!$D$4:$P$29,2,FALSE)*(VLOOKUP('Menu and cost - USA by city'!A16,COGS!$B$3:$I$10,8,FALSE)/3)*0.4 -> 5.3333333 | F16: =SUMPRODUCT(H16:L16,'Mean order price'!$C$3:$G$3)*G16+P16*'Mean order price'!$H$3 -> 4.4635 | G16: 0.3 | H16: 0.2 | I16: 0.5 | J16: 0.15 | K16: 0.05 | L16: 0.1 | M16: =SUM(H16:L16) -> 1 | N16: 10 | O16: =60/N16 -> 6 | P16: =O16/60 -> 0.1 | Q16: =E16-F16 -> 0.86983333 | R16: =Таблица1[[#This Row],[Profit]]/Таблица1[[#This Row],[Price]] -> 0.16309375 | S16: =VLOOKUP($A16,'Order Composition'!$B$2:$F$10,MATCH($C16,'Order Composition'!$B$2:$F$2,0),0) -> 0.55 | T16: =S16*Q16 -> 0.47840833 | U16: =Таблица1[[#This Row],[Price]]*Таблица1[[#This Row],[Order]] -> 2.9333333 | V16: =Таблица1[[#This Row],[Cost(with labour)]]*Таблица1[[#This Row],[Order]] -> 2.454925 | W16: =VLOOKUP($A16,'Mean order price'!$B$2:$H$10,7,0) -> 10 | X16: =W16*P16 -> 1
... A29: Columbus | B29: =B28+1 -> 26 | C29: Beverages | D29: Hot Drink B | E29: =VLOOKUP('Menu and cost - USA by city'!D29,'Menu and cost - Russia'!$D$4:$P$29,2,FALSE)*(VLOOKUP('Menu and cost - USA by city'!A29,COGS!$B$3:$I$10,8,FALSE)/3)*0.4 -> 2 | F29: =SUMPRODUCT(H29:L29,'Mean order price'!$C$3:$G$3)*G29+P29*'Mean order price'!$H$3 -> 1.574 | G29: 0.2 | H29: 0 | I29: 0 | J29: 0.1 | K29: 0.9 | L29: 0 | M29: =SUM(H29:L29) -> 1 | N29: 40 | O29: =60/N29 -> 1.5 | P29: =O29/60 -> 0.025 | Q29: =E29-F29 -> 0.426 | R29: =Таблица1[[#This Row],[Profit]]/Таблица1[[#This Row],[Price]] -> 0.213 | S29: =VLOOKUP($A29,'Order Composition'!$B$2:$F$10,MATCH($C29,'Order Composition'!$B$2:$F$2,0),0) -> 0.8 | T29: =S29*Q29 -> 0.3408 | U29: =Таблица1[[#This Row],[Price]]*Таблица1[[#This Row],[Order]] -> 1.6 | V29: =Таблица1[[#This Row],[Cost(with labour)]]*Таблица1[[#This Row],[Order]] -> 1.2592 | W29: =VLOOKUP($A29,'Mean order price'!$B$2:$H$10,7,0) -> 10 | X29: =W29*P29 -> 0.25
A30: Cincinnati | B30: =B29+1 -> 27 | C30: Appetizer | D30: Salad A | E30: =VLOOKUP('Menu and cost - USA by city'!D30,'Menu and cost - Russia'!$D$4:$P$29,2,FALSE)*(VLOOKUP('Menu and cost - USA by city'!A30,COGS!$B$3:$I$10,8,FALSE)/3)*0.4 -> 4.2 | F30: =SUMPRODUCT(H30:L30,'Mean order price'!$C$4:$G$4)*G30+P30*'Mean order price'!$H$4 -> 2.673 | G30: 0.2 | H30: 0 | I30: 0 | J30: 0.9 | K30: 0 | L30: 0.1 | M30: =SUM(H30:L30) -> 1 | N30: 20 | O30: =60/N30 -> 3 | P30: =O30/60 -> 0.05 | Q30: =E30-F30 -> 1.527 | R30: =Таблица1[[#This Row],[Profit]]/Таблица1[[#This Row],[Price]] -> 0.36357143 | S30: =VLOOKUP($A30,'Order Composition'!$B$2:$F$10,MATCH($C30,'Order Composition'!$B$2:$F$2,0),0) -> 0.55 | T30: =S30*Q30 -> 0.83985 | U30: =Таблица1[[#This Row],[Price]]*Таблица1[[#This Row],[Order]] -> 2.31 | V30: =Таблица1[[#This Row],[Cost(with labour)]]*Таблица1[[#This Row],[Order]] -> 1.47015 | W30: =VLOOKUP($A30,'Mean order price'!$B$2:$H$10,7,0) -> 10.5 | X30: =W30*P30 -> 0.525
A31: Cincinnati | B31: =B30+1 -> 28 | C31: Appetizer | D31: Salad B | E31: =VLOOKUP('Menu and cost - USA by city'!D31,'Menu and cost - Russia'!$D$4:$P$29,2,FALSE)*(VLOOKUP('Menu and cost - USA by city'!A31,COGS!$B$3:$I$10,8,FALSE)/3)*0.4 -> 4.2 | F31: =SUMPRODUCT(H31:L31,'Mean order price'!$C$4:$G$4)*G31+P31*'Mean order price'!$H$4 -> 2.7618 | G31: 0.2 | H31: 0 | I31: 0.2 | J31: 0.7 | K31: 0 | L31: 0.1 | M31: =SUM(H31:L31) -> 1 | N31: 20 | O31: =60/N31 -> 3 | P31: =O31/60 -> 0.05 | Q31: =E31-F31 -> 1.4382 | R31: =Таблица1[[#This Row],[Profit]]/Таблица1[[#This Row],[Price]] -> 0.34242857 | S31: =VLOOKUP($A31,'Order Composition'!$B$2:$F$10,MATCH($C31,'Order Composition'!$B$2:$F$2,0),0) -> 0.55 | T31: =S31*Q31 -> 0.79101 | U31: =Таблица1[[#This Row],[Price]]*Таблица1[[#This Row],[Order]] -> 2.31 | V31: =Таблица1[[#This Row],[Cost(with labour)]]*Таблица1[[#This Row],[Order]] -> 1.51899 | W31: =VLOOKUP($A31,'Mean order price'!$B$2:$H$10,7,0) -> 10.5 | X31: =W31*P31 -> 0.525
A32: Cincinnati | B32: =B31+1 -> 29 | C32: Appetizer | D32: Salad C | E32: =VLOOKUP('Menu and cost - USA by city'!D32,'Menu and cost - Russia'!$D$4:$P$29,2,FALSE)*(VLOOKUP('Menu and cost - USA by city'!A32,COGS!$B$3:$I$10,8,FALSE)/3)*0.4 -> 4.2 | F32: =SUMPRODUCT(H32:L32,'Mean order price'!$C$4:$G$4)*G32+P32*'Mean order price'!$H$4 -> 2.895 | G32: 0.2 | H32: 0 | I32: 0.5 | J32: 0.4 | K32: 0 | L32: 0.1 | M32: =SUM(H32:L32) -> 1 | N32: 20 | O32: =60/N32 -> 3 | P32: =O32/60 -> 0.05 | Q32: =E32-F32 -> 1.305 | R32: =Таблица1[[#This Row],[Profit]]/Таблица1[[#This Row],[Price]] -> 0.31071429 | S32: =VLOOKUP($A32,'Order Composition'!$B$2:$F$10,MATCH($C32,'Order Composition'!$B$2:$F$2,0),0) -> 0.55 | T32: =S32*Q32 -> 0.71775 | U32: =Таблица1[[#This Row],[Price]]*Таблица1[[#This Row],[Order]] -> 2.31 | V32: =Таблица1[[#This Row],[Cost(with labour)]]*Таблица1[[#This Row],[Order]] -> 1.59225 | W32: =VLOOKUP($A32,'Mean order price'!$B$2:$H$10,7,0) -> 10.5 | X32: =W32*P32 -> 0.525
A33: Cincinnati | B33: =B32+1 -> 30 | C33: Appetizer | D33: Soup A | E33: =VLOOKUP('Menu and cost - USA by city'!D33,'Menu and cost - Russia'!$D$4:$P$29,2,FALSE)*(VLOOKUP('Menu and cost - USA by city'!A33,COGS!$B$3:$I$10,8,FALSE)/3)*0.4 -> 2.8 | F33: =SUMPRODUCT(H33:L33,'Mean order price'!$C$4:$G$4)*G33+P33*'Mean order price'!$H$4 -> 1.7364 | G33: 0.2 | H33: 0.1 | I33: 0 | J33: 0.4 | K33: 0.1 | L33: 0.4 | M33: =SUM(H33:L33) -> 1 | N33: 60 | O33: =60/N33 -> 1 | P33: =O33/60 -> 0.016666667 | Q33: =E33-F33 -> 1.0636 | R33: =Таблица1[[#This Row],[Profit]]/Таблица1[[#This Row],[Price]] -> 0.37985714 | S33: =VLOOKUP($A33,'Order Composition'!$B$2:$F$10,MATCH($C33,'Order Composition'!$B$2:$F$2,0),0) -> 0.55 | T33: =S33*Q33 -> 0.58498 | U33: =Таблица1[[#This Row],[Price]]*Таблица1[[#This Row],[Order]] -> 1.54 | V33: =Таблица1[[#This Row],[Cost(with labour)]]*Таблица1[[#This Row],[Order]] -> 0.95502 | W33: =VLOOKUP($A33,'Mean order price'!$B$2:$H$10,7,0) -> 10.5 | X33: =W33*P33 -> 0.175
A34: Cincinnati | B34: =B33+1 -> 31 | C34: Appetizer | D34: Soup B | E34: =VLOOKUP('Menu and cost - USA by city'!D34,'Menu and cost - Russia'!$D$4:$P$29,2,FALSE)*(VLOOKUP('Menu and cost - USA by city'!A34,COGS!$B$3:$I$10,8,FALSE)/3)*0.4 -> 2.8 | F34: =SUMPRODUCT(H34:L34,'Mean order price'!$C$4:$G$4)*G34+P34*'Mean order price'!$H$4 -> 1.9452 | G34: 0.2 | H34: 0.1 | I34: 0.2 | J34: 0.3 | K34: 0.1 | L34: 0.3 | M34: =SUM(H34:L34) -> 1 | N34: 60 | O34: =60/N34 -> 1 | P34: =O34/60 -> 0.016666667 | Q34: =E34-F34 -> 0.8548 | R34: =Таблица1[[#This Row],[Profit]]/Таблица1[[#This Row],[Price]] -> 0.30528571 | S34: =VLOOKUP($A34,'Order Composition'!$B$2:$F$10,MATCH($C34,'Order Composition'!$B$2:$F$2,0),0) -> 0.55 | T34: =S34*Q34 -> 0.47014 | U34: =Таблица1[[#This Row],[Price]]*Таблица1[[#This Row],[Order]] -> 1.54 | V34: =Таблица1[[#This Row],[Cost(with labour)]]*Таблица1[[#This Row],[Order]] -> 1.06986 | W34: =VLOOKUP($A34,'Mean order price'!$B$2:$H$10,7,0) -> 10.5 | X34: =W34*P34 -> 0.175
A35: Cincinnati | B35: =B34+1 -> 32 | C35: Appetizer | D35: Pirozhok A | E35: =VLOOKUP('Menu and cost - USA by city'!D35,'Menu and cost - Russia'!$D$4:$P$29,2,FALSE)*(VLOOKUP('Menu and cost - USA by city'!A35,COGS!$B$3:$I$10,8,FALSE)/3)*0.4 -> 1.4 | F35: =SUMPRODUCT(H35:L35,'Mean order price'!$C$4:$G$4)*G35+P35*'Mean order price'!$H$4 -> 1.3446 | G35: 0.1 | H35: 0.1 | I35: 0 | J35: 0.75 | K35: 0.05 | L35: 0.1 | M35: =SUM(H35:L35) -> 1 | N35: 30 | O35: =60/N35 -> 2 | P35: =O35/60 -> 0.033333333 | Q35: =E35-F35 -> 0.0554 | R35: =Таблица1[[#This Row],[Profit]]/Таблица1[[#This Row],[Price]] -> 0.039571429 | S35: =VLOOKUP($A35,'Order Composition'!$B$2:$F$10,MATCH($C35,'Order Composition'!$B$2:$F$2,0),0) -> 0.55 | T35: =S35*Q35 -> 0.03047 | U35: =Таблица1[[#This Row],[Price]]*Таблица1[[#This Row],[Order]] -> 0.77 | V35: =Таблица1[[#This Row],[Cost(with labour)]]*Таблица1[[#This Row],[Order]] -> 0.73953 | W35: =VLOOKUP($A35,'Mean order price'!$B$2:$H$10,7,0) -> 10.5 | X35: =W35*P35 -> 0.35
A36: Cincinnati | B36: =B35+1 -> 33 | C36: Appetizer | D36: Pirozhok B | E36: =VLOOKUP('Menu and cost - USA by city'!D36,'Menu and cost - Russia'!$D$4:$P$29,2,FALSE)*(VLOOKUP('Menu and cost - USA by city'!A36,COGS!$B$3:$I$10,8,FALSE)/3)*0.4 -> 1.4 | F36: =SUMPRODUCT(H36:L36,'Mean order price'!$C$4:$G$4)*G36+P36*'Mean order price'!$H$4 -> 1.4556 | G36: 0.1 | H36: 0.1 | I36: 0.5 | J36: 0.25 | K36: 0.05 | L36: 0.1 | M36: =SUM(H36:L36) -> 1 | N36: 30 | O36: =60/N36 -> 2 | P36: =O36/60 -> 0.033333333 | Q36: =E36-F36 -> -0.0556 | R36: =Таблица1[[#This Row],[Profit]]/Таблица1[[#This Row],[Price]] -> -0.039714286 | S36: =VLOOKUP($A36,'Order Composition'!$B$2:$F$10,MATCH($C36,'Order Composition'!$B$2:$F$2,0),0) -> 0.55 | T36: =S36*Q36 -> -0.03058 | U36: =Таблица1[[#This Row],[Price]]*Таблица1[[#This Row],[Order]] -> 0.77 | V36: =Таблица1[[#This Row],[Cost(with labour)]]*Таблица1[[#This Row],[Order]] -> 0.80058 | W36: =VLOOKUP($A36,'Mean order price'!$B$2:$H$10,7,0) -> 10.5 | X36: =W36*P36 -> 0.35
A37: Cincinnati | B37: =B36+1 -> 34 | C37: Entry | D37: Blin A | E37: =VLOOKUP('Menu and cost - USA by city'!D37,'Menu and cost - Russia'!$D$4:$P$29,2,FALSE)*(VLOOKUP('Menu and cost - USA by city'!A37,COGS!$B$3:$I$10,8,FALSE)/3)*0.4 -> 4.2 | F37: =SUMPRODUCT(H37:L37,'Mean order price'!$C$4:$G$4)*G37+P37*'Mean order price'!$H$4 -> 2.6892 | G37: 0.2 | H37: 0.1 | I37: 0 | J37: 0.75 | K37: 0.05 | L37: 0.1 | M37: =SUM(H37:L37) -> 1 | N37: 15 | O37: =60/N37 -> 4 | P37: =O37/60 -> 0.066666667 | Q37: =E37-F37 -> 1.5108 | R37: =Таблица1[[#This Row],[Profit]]/Таблица1[[#This Row],[Price]] -> 0.35971429 | S37: =VLOOKUP($A37,'Order Composition'!$B$2:$F$10,MATCH($C37,'Order Composition'!$B$2:$F$2,0),0) -> 0.6 | T37: =S37*Q37 -> 0.90648 | U37: =Таблица1[[#This Row],[Price]]*Таблица1[[#This Row],[Order]] -> 2.52 | V37: =Таблица1[[#This Row],[Cost(with labour)]]*Таблица1[[#This Row],[Order]] -> 1.61352 | W37: =VLOOKUP($A37,'Mean order price'!$B$2:$H$10,7,0) -> 10.5 | X37: =W37*P37 -> 0.7
A38: Cincinnati | B38: =B37+1 -> 35 | C38: Entry | D38: Blin B | E38: =VLOOKUP('Menu and cost - USA by city'!D38,'Menu and cost - Russia'!$D$4:$P$29,2,FALSE)*(VLOOKUP('Menu and cost - USA by city'!A38,COGS!$B$3:$I$10,8,FALSE)/3)*0.4 -> 4.2 | F38: =SUMPRODUCT(H38:L38,'Mean order price'!$C$4:$G$4)*G38+P38*'Mean order price'!$H$4 -> 3.4108 | G38: 0.3 | H38: 0.3 | I38: 0 | J38: 0.55 | K38: 0.05 | L38: 0.1 | M38: =SUM(H38:L38) -> 1 | N38: 15 | O38: =60/N38 -> 4 | P38: =O38/60 -> 0.066666667 | Q38: =E38-F38 -> 0.7892 | R38: =Таблица1[[#This Row],[Profit]]/Таблица1[[#This Row],[Price]] -> 0.18790476 | S38: =VLOOKUP($A38,'Order Composition'!$B$2:$F$10,MATCH($C38,'Order Composition'!$B$2:$F$2,0),0) -> 0.6 | T38: =S38*Q38 -> 0.47352 | U38: =Таблица1[[#This Row],[Price]]*Таблица1[[#This Row],[Order]] -> 2.52 | V38: =Таблица1[[#This Row],[Cost(with labour)]]*Таблица1[[#This Row],[Order]] -> 2.04648 | W38: =VLOOKUP($A38,'Mean order price'!$B$2:$H$10,7,0) -> 10.5 | X38: =W38*P38 -> 0.7
A39: Cincinnati | B39: =B38+1 -> 36 | C39: Entry | D39: Blin C | E39: =VLOOKUP('Menu and cost - USA by city'!D39,'Menu and cost - Russia'!$D$4:$P$29,2,FALSE)*(VLOOKUP('Menu and cost - USA by city'!A39,COGS!$B$3:$I$10,8,FALSE)/3)*0.4 -> 4.2 | F39: =SUMPRODUCT(H39:L39,'Mean order price'!$C$4:$G$4)*G39+P39*'Mean order price'!$H$4 -> 3.8503 | G39: 0.3 | H39: 0.1 | I39: 0.25 | J39: 0.5 | K39: 0.05 | L39: 0.1 | M39: =SUM(H39:L39) -> 1 | N39: 15 | O39: =60/N39 -> 4 | P39: =O39/60 -> 0.066666667 | Q39: =E39-F39 -> 0.3497 | R39: =Таблица1[[#This Row],[Profit]]/Таблица1[[#This Row],[Price]] -> 0.083261905 | S39: =VLOOKUP($A39,'Order Composition'!$B$2:$F$10,MATCH($C39,'Order Composition'!$B$2:$F$2,0),0) -> 0.6 | T39: =S39*Q39 -> 0.20982 | U39: =Таблица1[[#This Row],[Price]]*Таблица1[[#This Row],[Order]] -> 2.52 | V39: =Таблица1[[#This Row],[Cost(with labour)]]*Таблица1[[#This Row],[Order]] -> 2.31018 | W39: =VLOOKUP($A39,'Mean order price'!$B$2:$H$10,7,0) -> 10.5 | X39: =W39*P39 -> 0.7
A40: Cincinnati | B40: =B39+1 -> 37 | C40: Entry | D40: Blin D | E40: =VLOOKUP('Menu and cost - USA by city'!D40,'Menu and cost - Russia'!$D$4:$P$29,2,FALSE)*(VLOOKUP('Menu and cost - USA by city'!A40,COGS!$B$3:$I$10,8,FALSE)/3)*0.4 -> 4.2 | F40: =SUMPRODUCT(H40:L40,'Mean order price'!$C$4:$G$4)*G40+P40*'Mean order price'!$H$4 -> 3.1258 | G40: 0.2 | H40: 0.2 | I40: 0.4 | J40: 0.25 | K40: 0.05 | L40: 0.1 | M40: =SUM(H40:L40) -> 1 | N40: 10 | O40: =60/N40 -> 6 | P40: =O40/60 -> 0.1 | Q40: =E40-F40 -> 1.0742 | R40: =Таблица1[[#This Row],[Profit]]/Таблица1[[#This Row],[Price]] -> 0.2557619 | S40: =VLOOKUP($A40,'Order Composition'!$B$2:$F$10,MATCH($C40,'Order Composition'!$B$2:$F$2,0),0) -> 0.6 | T40: =S40*Q40 -> 0.64452 | U40: =Таблица1[[#This Row],[Price]]*Таблица1[[#This Row],[Order]] -> 2.52 | V40: =Таблица1[[#This Row],[Cost(with labour)]]*Таблица1[[#This Row],[Order]] -> 1.87548 | W40: =VLOOKUP($A40,'Mean order price'!$B$2:$H$10,7,0) -> 10.5 | X40: =W40*P40 -> 1.05
A41: Cincinnati | B41: =B40+1 -> 38 | C41: Entry | D41: Blin E | E41: =VLOOKUP('Menu and cost - USA by city'!D41,'Menu and cost - Russia'!$D$4:$P$29,2,FALSE)*(VLOOKUP('Menu and cost - USA by city'!A41,COGS!$B$3:$I$10,8,FALSE)/3)*0.4 -> 5.6 | F41: =SUMPRODUCT(H41:L41,'Mean order price'!$C$4:$G$4)*G41+P41*'Mean order price'!$H$4 -> 4.2969 | G41: 0.3 | H41: 0.2 | I41: 0.6 | J41: 0.05 | K41: 0.05 | L41: 0.1 | M41: =SUM(H41:L41) -> 1 | N41: 10 | O41: =60/N41 -> 6 | P41: =O41/60 -> 0.1 | Q41: =E41-F41 -> 1.3031 | R41: =Таблица1[[#This Row],[Profit]]/Таблица1[[#This Row],[Price]] -> 0.23269643 | S41: =VLOOKUP($A41,'Order Composition'!$B$2:$F$10,MATCH($C41,'Order Composition'!$B$2:$F$2,0),0) -> 0.6 | T41: =S41*Q41 -> 0.78186 | U41: =Таблица1[[#This Row],[Price]]*Таблица1[[#This Row],[Order]] -> 3.36 | V41: =Таблица1[[#This Row],[Cost(with labour)]]*Таблица1[[#This Row],[Order]] -> 2.57814 | W41: =VLOOKUP($A41,'Mean order price'!$B$2:$H$10,7,0) -> 10.5 | X41: =W41*P41 -> 1.05
... A55: Cincinnati | B55: =B54+1 -> 52 | C55: Beverages | D55: Hot Drink B | E55: =VLOOKUP('Menu and cost - USA by city'!D55,'Menu and cost - Russia'!$D$4:$P$29,2,FALSE)*(VLOOKUP('Menu and cost - USA by city'!A55,COGS!$B$3:$I$10,8,FALSE)/3)*0.4 -> 2.1 | F55: =SUMPRODUCT(H55:L55,'Mean order price'!$C$4:$G$4)*G55+P55*'Mean order price'!$H$4 -> 1.3101 | G55: 0.2 | H55: 0 | I55: 0 | J55: 0.1 | K55: 0.9 | L55: 0 | M55: =SUM(H55:L55) -> 1 | N55: 40 | O55: =60/N55 -> 1.5 | P55: =O55/60 -> 0.025 | Q55: =E55-F55 -> 0.7899 | R55: =Таблица1[[#This Row],[Profit]]/Таблица1[[#This Row],[Price]] -> 0.37614286 | S55: =VLOOKUP($A55,'Order Composition'!$B$2:$F$10,MATCH($C55,'Order Composition'!$B$2:$F$2,0),0) -> 0.8 | T55: =S55*Q55 -> 0.63192 | U55: =Таблица1[[#This Row],[Price]]*Таблица1[[#This Row],[Order]] -> 1.68 | V55: =Таблица1[[#This Row],[Cost(with labour)]]*Таблица1[[#This Row],[Order]] -> 1.04808 | W55: =VLOOKUP($A55,'Mean order price'!$B$2:$H$10,7,0) -> 10.5 | X55: =W55*P55 -> 0.2625
A56: Cleveland | B56: =B55+1 -> 53 | C56: Appetizer | D56: Salad A | E56: =VLOOKUP('Menu and cost - USA by city'!D56,'Menu and cost - Russia'!$D$4:$P$29,2,FALSE)*(VLOOKUP('Menu and cost - USA by city'!A56,COGS!$B$3:$I$10,8,FALSE)/3)*0.4 -> 4.4 | F56: =SUMPRODUCT(H56:L56,'Mean order price'!$C$5:$G$5)*G56+P56*'Mean order price'!$H$5 -> 2.905 | G56: 0.2 | H56: 0 | I56: 0 | J56: 0.9 | K56: 0 | L56: 0.1 | M56: =SUM(H56:L56) -> 1 | N56: 20 | O56: =60/N56 -> 3 | P56: =O56/60 -> 0.05 | Q56: =E56-F56 -> 1.495 | R56: =Таблица1[[#This Row],[Profit]]/Таблица1[[#This Row],[Price]] -> 0.33977273 | S56: =VLOOKUP($A56,'Order Composition'!$B$2:$F$10,MATCH($C56,'Order Composition'!$B$2:$F$2,0),0) -> 0.4 | T56: =S56*Q56 -> 0.598 | U56: =Таблица1[[#This Row],[Price]]*Таблица1[[#This Row],[Order]] -> 1.76 | V56: =Таблица1[[#This Row],[Cost(with labour)]]*Таблица1[[#This Row],[Order]] -> 1.162 | W56: =VLOOKUP($A56,'Mean order price'!$B$2:$H$10,7,0) -> 11 | X56: =W56*P56 -> 0.55
A57: Cleveland | B57: =B56+1 -> 54 | C57: Appetizer | D57: Salad B | E57: =VLOOKUP('Menu and cost - USA by city'!D57,'Menu and cost - Russia'!$D$4:$P$29,2,FALSE)*(VLOOKUP('Menu and cost - USA by city'!A57,COGS!$B$3:$I$10,8,FALSE)/3)*0.4 -> 4.4 | F57: =SUMPRODUCT(H57:L57,'Mean order price'!$C$5:$G$5)*G57+P57*'Mean order price'!$H$5 -> 2.959 | G57: 0.2 | H57: 0 | I57: 0.2 | J57: 0.7 | K57: 0 | L57: 0.1 | M57: =SUM(H57:L57) -> 1 | N57: 20 | O57: =60/N57 -> 3 | P57: =O57/60 -> 0.05 | Q57: =E57-F57 -> 1.441 | R57: =Таблица1[[#This Row],[Profit]]/Таблица1[[#This Row],[Price]] -> 0.3275 | S57: =VLOOKUP($A57,'Order Composition'!$B$2:$F$10,MATCH($C57,'Order Composition'!$B$2:$F$2,0),0) -> 0.4 | T57: =S57*Q57 -> 0.5764 | U57: =Таблица1[[#This Row],[Price]]*Таблица1[[#This Row],[Order]] -> 1.76 | V57: =Таблица1[[#This Row],[Cost(with labour)]]*Таблица1[[#This Row],[Order]] -> 1.1836 | W57: =VLOOKUP($A57,'Mean order price'!$B$2:$H$10,7,0) -> 11 | X57: =W57*P57 -> 0.55
A58: Cleveland | B58: =B57+1 -> 55 | C58: Appetizer | D58: Salad C | E58: =VLOOKUP('Menu and cost - USA by city'!D58,'Menu and cost - Russia'!$D$4:$P$29,2,FALSE)*(VLOOKUP('Menu and cost - USA by city'!A58,COGS!$B$3:$I$10,8,FALSE)/3)*0.4 -> 4.4 | F58: =SUMPRODUCT(H58:L58,'Mean order price'!$C$5:$G$5)*G58+P58*'Mean order price'!$H$5 -> 3.04 | G58: 0.2 | H58: 0 | I58: 0.5 | J58: 0.4 | K58: 0 | L58: 0.1 | M58: =SUM(H58:L58) -> 1 | N58: 20 | O58: =60/N58 -> 3 | P58: =O58/60 -> 0.05 | Q58: =E58-F58 -> 1.36 | R58: =Таблица1[[#This Row],[Profit]]/Таблица1[[#This Row],[Price]] -> 0.30909091 | S58: =VLOOKUP($A58,'Order Composition'!$B$2:$F$10,MATCH($C58,'Order Composition'!$B$2:$F$2,0),0) -> 0.4 | T58: =S58*Q58 -> 0.544 | U58: =Таблица1[[#This Row],[Price]]*Таблица1[[#This Row],[Order]] -> 1.76 | V58: =Таблица1[[#This Row],[Cost(with labour)]]*Таблица1[[#This Row],[Order]] -> 1.216 | W58: =VLOOKUP($A58,'Mean order price'!$B$2:$H$10,7,0) -> 11 | X58: =W58*P58 -> 0.55
A59: Cleveland | B59: =B58+1 -> 56 | C59: Appetizer | D59: Soup A | E59: =VLOOKUP('Menu and cost - USA by city'!D59,'Menu and cost - Russia'!$D$4:$P$29,2,FALSE)*(VLOOKUP('Menu and cost - USA by city'!A59,COGS!$B$3:$I$10,8,FALSE)/3)*0.4 -> 2.9333333 | F59: =SUMPRODUCT(H59:L59,'Mean order price'!$C$5:$G$5)*G59+P59*'Mean order price'!$H$5 -> 1.8639333 | G59: 0.2 | H59: 0.1 | I59: 0 | J59: 0.4 | K59: 0.1 | L59: 0.4 | M59: =SUM(H59:L59) -> 1 | N59: 60 | O59: =60/N59 -> 1 | P59: =O59/60 -> 0.016666667 | Q59: =E59-F59 -> 1.0694 | R59: =Таблица1[[#This Row],[Profit]]/Таблица1[[#This Row],[Price]] -> 0.36456818 | S59: =VLOOKUP($A59,'Order Composition'!$B$2:$F$10,MATCH($C59,'Order Composition'!$B$2:$F$2,0),0) -> 0.4 | T59: =S59*Q59 -> 0.42776 | U59: =Таблица1[[#This Row],[Price]]*Таблица1[[#This Row],[Order]] -> 1.1733333 | V59: =Таблица1[[#This Row],[Cost(with labour)]]*Таблица1[[#This Row],[Order]] -> 0.74557333 | W59: =VLOOKUP($A59,'Mean order price'!$B$2:$H$10,7,0) -> 11 | X59: =W59*P59 -> 0.18333333
A60: Cleveland | B60: =B59+1 -> 57 | C60: Appetizer | D60: Soup B | E60: =VLOOKUP('Menu and cost - USA by city'!D60,'Menu and cost - Russia'!$D$4:$P$29,2,FALSE)*(VLOOKUP('Menu and cost - USA by city'!A60,COGS!$B$3:$I$10,8,FALSE)/3)*0.4 -> 2.9333333 | F60: =SUMPRODUCT(H60:L60,'Mean order price'!$C$5:$G$5)*G60+P60*'Mean order price'!$H$5 -> 2.0529333 | G60: 0.2 | H60: 0.1 | I60: 0.2 | J60: 0.3 | K60: 0.1 | L60: 0.3 | M60: =SUM(H60:L60) -> 1 | N60: 60 | O60: =60/N60 -> 1 | P60: =O60/60 -> 0.016666667 | Q60: =E60-F60 -> 0.8804 | R60: =Таблица1[[#This Row],[Profit]]/Таблица1[[#This Row],[Price]] -> 0.30013636 | S60: =VLOOKUP($A60,'Order Composition'!$B$2:$F$10,MATCH($C60,'Order Composition'!$B$2:$F$2,0),0) -> 0.4 | T60: =S60*Q60 -> 0.35216 | U60: =Таблица1[[#This Row],[Price]]*Таблица1[[#This Row],[Order]] -> 1.1733333 | V60: =Таблица1[[#This Row],[Cost(with labour)]]*Таблица1[[#This Row],[Order]] -> 0.82117333 | W60: =VLOOKUP($A60,'Mean order price'!$B$2:$H$10,7,0) -> 11 | X60: =W60*P60 -> 0.18333333
A61: Cleveland | B61: =B60+1 -> 58 | C61: Appetizer | D61: Pirozhok A | E61: =VLOOKUP('Menu and cost - USA by city'!D61,'Menu and cost - Russia'!$D$4:$P$29,2,FALSE)*(VLOOKUP('Menu and cost - USA by city'!A61,COGS!$B$3:$I$10,8,FALSE)/3)*0.4 -> 1.4666667 | F61: =SUMPRODUCT(H61:L61,'Mean order price'!$C$5:$G$5)*G61+P61*'Mean order price'!$H$5 -> 1.4457167 | G61: 0.1 | H61: 0.1 | I61: 0 | J61: 0.75 | K61: 0.05 | L61: 0.1 | M61: =SUM(H61:L61) -> 1 | N61: 30 | O61: =60/N61 -> 2 | P61: =O61/60 -> 0.033333333 | Q61: =E61-F61 -> 0.02095 | R61: =Таблица1[[#This Row],[Profit]]/Таблица1[[#This Row],[Price]] -> 0.014284091 | S61: =VLOOKUP($A61,'Order Composition'!$B$2:$F$10,MATCH($C61,'Order Composition'!$B$2:$F$2,0),0) -> 0.4 | T61: =S61*Q61 -> 0.00838 | U61: =Таблица1[[#This Row],[Price]]*Таблица1[[#This Row],[Order]] -> 0.58666667 | V61: =Таблица1[[#This Row],[Cost(with labour)]]*Таблица1[[#This Row],[Order]] -> 0.57828667 | W61: =VLOOKUP($A61,'Mean order price'!$B$2:$H$10,7,0) -> 11 | X61: =W61*P61 -> 0.36666667
A62: Cleveland | B62: =B61+1 -> 59 | C62: Appetizer | D62: Pirozhok B | E62: =VLOOKUP('Menu and cost - USA by city'!D62,'Menu and cost - Russia'!$D$4:$P$29,2,FALSE)*(VLOOKUP('Menu and cost - USA by city'!A62,COGS!$B$3:$I$10,8,FALSE)/3)*0.4 -> 1.4666667 | F62: =SUMPRODUCT(H62:L62,'Mean order price'!$C$5:$G$5)*G62+P62*'Mean order price'!$H$5 -> 1.5132167 | G62: 0.1 | H62: 0.1 | I62: 0.5 | J62: 0.25 | K62: 0.05 | L62: 0.1 | M62: =SUM(H62:L62) -> 1 | N62: 30 | O62: =60/N62 -> 2 | P62: =O62/60 -> 0.033333333 | Q62: =E62-F62 -> -0.04655 | R62: =Таблица1[[#This Row],[Profit]]/Таблица1[[#This Row],[Price]] -> -0.031738636 | S62: =VLOOKUP($A62,'Order Composition'!$B$2:$F$10,MATCH($C62,'Order Composition'!$B$2:$F$2,0),0) -> 0.4 | T62: =S62*Q62 -> -0.01862 | U62: =Таблица1[[#This Row],[Price]]*Таблица1[[#This Row],[Order]] -> 0.58666667 | V62: =Таблица1[[#This Row],[Cost(with labour)]]*Таблица1[[#This Row],[Order]] -> 0.60528667 | W62: =VLOOKUP($A62,'Mean order price'!$B$2:$H$10,7,0) -> 11 | X62: =W62*P62 -> 0.36666667
A63: Cleveland | B63: =B62+1 -> 60 | C63: Entry | D63: Blin A | E63: =VLOOKUP('Menu and cost - USA by city'!D63,'Menu and cost - Russia'!$D$4:$P$29,2,FALSE)*(VLOOKUP('Menu and cost - USA by city'!A63,COGS!$B$3:$I$10,8,FALSE)/3)*0.4 -> 4.4 | F63: =SUMPRODUCT(H63:L63,'Mean order price'!$C$5:$G$5)*G63+P63*'Mean order price'!$H$5 -> 2.8914333 | G63: 0.2 | H63: 0.1 | I63: 0 | J63: 0.75 | K63: 0.05 | L63: 0.1 | M63: =SUM(H63:L63) -> 1 | N63: 15 | O63: =60/N63 -> 4 | P63: =O63/60 -> 0.066666667 | Q63: =E63-F63 -> 1.5085667 | R63: =Таблица1[[#This Row],[Profit]]/Таблица1[[#This Row],[Price]] -> 0.34285606 | S63: =VLOOKUP($A63,'Order Composition'!$B$2:$F$10,MATCH($C63,'Order Composition'!$B$2:$F$2,0),0) -> 0.85 | T63: =S63*Q63 -> 1.2822817 | U63: =Таблица1[[#This Row],[Price]]*Таблица1[[#This Row],[Order]] -> 3.74 | V63: =Таблица1[[#This Row],[Cost(with labour)]]*Таблица1[[#This Row],[Order]] -> 2.4577183 | W63: =VLOOKUP($A63,'Mean order price'!$B$2:$H$10,7,0) -> 11 | X63: =W63*P63 -> 0.73333333
A64: Cleveland | B64: =B63+1 -> 61 | C64: Entry | D64: Blin B | E64: =VLOOKUP('Menu and cost - USA by city'!D64,'Menu and cost - Russia'!$D$4:$P$29,2,FALSE)*(VLOOKUP('Menu and cost - USA by city'!A64,COGS!$B$3:$I$10,8,FALSE)/3)*0.4 -> 4.4 | F64: =SUMPRODUCT(H64:L64,'Mean order price'!$C$5:$G$5)*G64+P64*'Mean order price'!$H$5 -> 3.5972833 | G64: 0.3 | H64: 0.3 | I64: 0 | J64: 0.55 | K64: 0.05 | L64: 0.1 | M64: =SUM(H64:L64) -> 1 | N64: 15 | O64: =60/N64 -> 4 | P64: =O64/60 -> 0.066666667 | Q64: =E64-F64 -> 0.80271667 | R64: =Таблица1[[#This Row],[Profit]]/Таблица1[[#This Row],[Price]] -> 0.18243561 | S64: =VLOOKUP($A64,'Order Composition'!$B$2:$F$10,MATCH($C64,'Order Composition'!$B$2:$F$2,0),0) -> 0.85 | T64: =S64*Q64 -> 0.68230917 | U64: =Таблица1[[#This Row],[Price]]*Таблица1[[#This Row],[Order]] -> 3.74 | V64: =Таблица1[[#This Row],[Cost(with labour)]]*Таблица1[[#This Row],[Order]] -> 3.0576908 | W64: =VLOOKUP($A64,'Mean order price'!$B$2:$H$10,7,0) -> 11 | X64: =W64*P64 -> 0.73333333
A65: Cleveland | B65: =B64+1 -> 62 | C65: Entry | D65: Blin C | E65: =VLOOKUP('Menu and cost - USA by city'!D65,'Menu and cost - Russia'!$D$4:$P$29,2,FALSE)*(VLOOKUP('Menu and cost - USA by city'!A65,COGS!$B$3:$I$10,8,FALSE)/3)*0.4 -> 4.4 | F65: =SUMPRODUCT(H65:L65,'Mean order price'!$C$5:$G$5)*G65+P65*'Mean order price'!$H$5 -> 4.0717333 | G65: 0.3 | H65: 0.1 | I65: 0.25 | J65: 0.5 | K65: 0.05 | L65: 0.1 | M65: =SUM(H65:L65) -> 1 | N65: 15 | O65: =60/N65 -> 4 | P65: =O65/60 -> 0.066666667 | Q65: =E65-F65 -> 0.32826667 | R65: =Таблица1[[#This Row],[Profit]]/Таблица1[[#This Row],[Price]] -> 0.074606061 | S65: =VLOOKUP($A65,'Order Composition'!$B$2:$F$10,MATCH($C65,'Order Composition'!$B$2:$F$2,0),0) -> 0.85 | T65: =S65*Q65 -> 0.27902667 | U65: =Таблица1[[#This Row],[Price]]*Таблица1[[#This Row],[Order]] -> 3.74 | V65: =Таблица1[[#This Row],[Cost(with labour)]]*Таблица1[[#This Row],[Order]] -> 3.4609733 | W65: =VLOOKUP($A65,'Mean order price'!$B$2:$H$10,7,0) -> 11 | X65: =W65*P65 -> 0.73333333
A66: Cleveland | B66: =B65+1 -> 63 | C66: Entry | D66: Blin D | E66: =VLOOKUP('Menu and cost - USA by city'!D66,'Menu and cost - Russia'!$D$4:$P$29,2,FALSE)*(VLOOKUP('Menu and cost - USA by city'!A66,COGS!$B$3:$I$10,8,FALSE)/3)*0.4 -> 4.4 | F66: =SUMPRODUCT(H66:L66,'Mean order price'!$C$5:$G$5)*G66+P66*'Mean order price'!$H$5 -> 3.2417 | G66: 0.2 | H66: 0.2 | I66: 0.4 | J66: 0.25 | K66: 0.05 | L66: 0.1 | M66: =SUM(H66:L66) -> 1 | N66: 10 | O66: =60/N66 -> 6 | P66: =O66/60 -> 0.1 | Q66: =E66-F66 -> 1.1583 | R66: =Таблица1[[#This Row],[Profit]]/Таблица1[[#This Row],[Price]] -> 0.26325 | S66: =VLOOKUP($A66,'Order Composition'!$B$2:$F$10,MATCH($C66,'Order Composition'!$B$2:$F$2,0),0) -> 0.85 | T66: =S66*Q66 -> 0.984555 | U66: =Таблица1[[#This Row],[Price]]*Таблица1[[#This Row],[Order]] -> 3.74 | V66: =Таблица1[[#This Row],[Cost(with labour)]]*Таблица1[[#This Row],[Order]] -> 2.755445 | W66: =VLOOKUP($A66,'Mean order price'!$B$2:$H$10,7,0) -> 11 | X66: =W66*P66 -> 1.1
A67: Cleveland | B67: =B66+1 -> 64 | C67: Entry | D67: Blin E | E67: =VLOOKUP('Menu and cost - USA by city'!D67,'Menu and cost - Russia'!$D$4:$P$29,2,FALSE)*(VLOOKUP('Menu and cost - USA by city'!A67,COGS!$B$3:$I$10,8,FALSE)/3)*0.4 -> 5.8666667 | F67: =SUMPRODUCT(H67:L67,'Mean order price'!$C$5:$G$5)*G67+P67*'Mean order price'!$H$5 -> 4.39355 | G67: 0.3 | H67: 0.2 | I67: 0.6 | J67: 0.05 | K67: 0.05 | L67: 0.1 | M67: =SUM(H67:L67) -> 1 | N67: 10 | O67: =60/N67 -> 6 | P67: =O67/60 -> 0.1 | Q67: =E67-F67 -> 1.4731167 | R67: =Таблица1[[#This Row],[Profit]]/Таблица1[[#This Row],[Price]] -> 0.25109943 | S67: =VLOOKUP($A67,'Order Composition'!$B$2:$F$10,MATCH($C67,'Order Composition'!$B$2:$F$2,0),0) -> 0.85 | T67: =S67*Q67 -> 1.2521492 | U67: =Таблица1[[#This Row],[Price]]*Таблица1[[#This Row],[Order]] -> 4.9866667 | V67: =Таблица1[[#This Row],[Cost(with labour)]]*Таблица1[[#This Row],[Order]] -> 3.7345175 | W67: =VLOOKUP($A67,'Mean order price'!$B$2:$H$10,7,0) -> 11 | X67: =W67*P67 -> 1.1
...

Sheet Pivot tables
A1: Category | B1: (Все)
G2: Среднее по категориям
A3: Названия строк | B3: Среднее по полю Price | C3: Среднее по полю Cost(with labour) | D3: Среднее по полю Profit | G3: Названия строк | H3: Среднее по полю Gross profit margin
A4: Portland | B4: 4.9179487 | C4: 3.0146462 | D4: 1.9033026 | G4: Birmingham | H4: 0.15490164
A5: Cleveland | B5: 3.8641026 | C5: 2.5339865 | D5: 1.330116 | G5: Cincinnati | H5: 0.352317
A6: Cincinnati | B6: 3.6884615 | C6: 2.3889538 | D6: 1.2995077 | G6: Cleveland | H6: 0.34422379
A7: Columbus | B7: 3.5128205 | C7: 2.6082115 | D7: 0.90460897 | G7: Columbus | H7: 0.25751642
A8: Indianapolis | B8: 2.8102564 | C8: 2.123125 | D8: 0.68713141 | G8: Indianapolis | H8: 0.24450844
A9: Birmingham | B9: 3.5128205 | C9: 2.9686788 | D9: 0.54414167 | G9: Las Vegas | H9: -0.10839173
A10: Miami | B10: 3.3371795 | C10: 3.3444288 | D10: -0.007249359 | G10: Miami | H10: -0.0021723012
A11: Las Vegas | B11: 3.1615385 | C11: 3.5042231 | D11: -0.34268462 | G11: Portland | H11: 0.38701147
A12: Общий итог | B12: 3.600641 | C12: 2.8107817 | D12: 0.78985929 | G12: Общий итог | H12: 0.2193663
G16: Profit each Order
G17: Среднее по полю Order * Profit | H17: Названия столбцов
A18: Названия строк | B18: Сумма по полю Order * Profit | C18: Сумма по полю Order * Profit2 | G18: Названия строк | H18: Appetizer | I18: Beverages | J18: Dessert | K18: Entry | L18: Summ Order Profit
A19: Fruit Blin B | B19: 0.25090302 | C19: 6.3257717 | G19: Birmingham | H19: 0.059305714 | I19: 0.16491667 | J19: 0.63164 | K19: 0.42521158 | L19: =SUM(H19:K19) -> 1.281074
A20: Portland | B20: 0.29370224 | C20: 1.8578933 | G20: Cincinnati | H20: 0.48623143 | I20: 0.90666667 | J20: 0.7764 | K20: 0.898548 | L20: =SUM(H20:K20) -> 3.0678461
A21: Cleveland | B21: 0.2194233 | C21: 1.3880217 | G21: Cleveland | H21: 0.35544 | I21: 0.82520833 | J21: 1.1081156 | K21: 1.3359351 | L21: =SUM(H21:K21) -> 3.624699
A22: Cincinnati | B22: 0.15193087 | C22: 0.96108 | G22: Columbus | H22: 0.16909714 | I22: 0.60364444 | J22: 0.57079556 | K22: 0.55849017 | L22: =SUM(H22:K22) -> 1.9020273
A23: Columbus | B23: 0.10036457 | C23: 0.63488333 | G23: Indianapolis | H23: 0.1614 | I23: 0.49768889 | J23: 0.86707111 | K23: 0.438383 | L23: =SUM(H23:K23) -> 1.964543
A24: Indianapolis | B24: 0.092086789 | C24: 0.58252 | G24: Las Vegas | H24: -0.23294071 | I24: -0.19005 | J24: 0.55617333 | K24: -0.635553 | L24: =SUM(H24:K24) -> -0.50237038
A25: Birmingham | B25: 0.08462156 | C25: 0.53529667 | G25: Miami | H25: -0.066078571 | I25: -0.040744444 | J25: 0.83372444 | K25: -0.18126392 | L25: =SUM(H25:K25) -> 0.54563751
A26: Miami | B26: 0.0459907 | C26: 0.29092667 | G26: Portland | H26: 0.507065 | I26: 1.0842139 | J26: 1.3567778 | K26: 1.9484987 | L26: =SUM(H26:K26) -> 4.8965553
A27: Las Vegas | B27: 0.011879974 | C27: 0.07515 | G27: Общий итог | H27: 0.17994 | I27: 0.48144306 | J27: 0.83758722 | K27: 0.5985312
A28: Veggie Blin A | B28: 0.23364775 | C28: 5.8907317
A29: Portland | B29: 0.30382191 | C29: 1.7897333
A30: Cleveland | B30: 0.21767783 | C30: 1.2822817 | P30: =15*12 -> 180
A31: Cincinnati | B31: 0.15388241 | C31: 0.90648 | P31: =1000000/180000 -> 5.5555556
A32: Columbus | B32: 0.099410967 | C32: 0.58560333
A33: Indianapolis | B33: 0.08882428 | C33: 0.52324 | G33: Среднее по полю Profit | H33: Названия столбцов
A34: Birmingham | B34: 0.080233949 | C34: 0.47263667 | G34: Названия строк | H34: Appetizer | I34: Beverages | J34: Dessert | K34: Entry | L34: Общий итог
A35: Miami | B35: 0.046385862 | C35: 0.27324667 | G35: Birmingham | H35: 0.29652857 | I35: 0.21988889 | J35: 1.4036444 | K35: 0.65417167 | L35: 0.54414167
A36: Las Vegas | B36: 0.009762794 | C36: 0.05751 | G36: Cincinnati | H36: 0.88405714 | I36: 1.1333333 | J36: 1.941 | K36: 1.49758 | L36: 1.2995077
A37: Blin A | B37: 0.23364775 | C37: 5.8907317 | G37: Cleveland | H37: 0.8886 | I37: 1.1002778 | J37: 2.0147556 | K37: 1.5716883 | L37: 1.330116
A38: Portland | B38: 0.30382191 | C38: 1.7897333 | G38: Columbus | H38: 0.56365714 | I38: 0.75455556 | J38: 1.6308444 | K38: 1.0154367 | L38: 0.90460897
A39: Cleveland | B39: 0.21767783 | C39: 1.2822817 | G39: Indianapolis | H39: 0.4035 | I39: 0.62211111 | J39: 1.3339556 | K39: 0.73063833 | L39: 0.68713141
A40: Cincinnati | B40: 0.15388241 | C40: 0.90648 | G40: Las Vegas | H40: -0.42352857 | I40: -0.21116667 | J40: 0.79453333 | K40: -0.70617 | L40: -0.34268462
A41: Columbus | B41: 0.099410967 | C41: 0.58560333 | G41: Miami | H41: -0.13215714 | I41: -0.042888889 | J41: 1.0421556 | K41: -0.21325167 | L41: -0.007249359
A42: Indianapolis | B42: 0.08882428 | C42: 0.52324 | G42: Portland | H42: 1.4487571 | I42: 1.1412778 | J42: 2.7135556 | K42: 2.4356233 | L42: 1.9033026
A43: Birmingham | B43: 0.080233949 | C43: 0.47263667 | G43: Общий итог | H43: 0.49117679 | I43: 0.58967361 | J43: 1.6093056 | K43: 0.87321458 | L43: 0.78985929
...

Sheet Revenue&Margin
A1: Tables | B1: =B3+B4 -> 10
A2: Seats at the table | B2: =4*2+6*4 -> 32
A3: table for 4 person | B3: 6
A4: table for 2 person | B4: 4
A5: Hours opening per day (8-20) | B5: =B7-B6 -> 12
A6: open | B6: 8
A7: close | B7: 20
A8: Hours inside | B8: =B5*0.8 -> 9.6
